<?xml version="1.0" encoding="utf-8"?>
  <robot name="my_six_force_robot1"  xmlns:xacro="http://www.ros.org/wiki/xacro">
  <link name="robot1_six_force_sensor_link">
    <inertial>
      <mass value="10"/>
      <inertia ixx="0.0036400000000000004" ixy="0" ixz="0" iyy="0.0036400000000000004" iyz="0" izz="0.00578"/>
    </inertial>
    <visual>
      <origin rpy="0 0 0" xyz="0 0 0"/>
      <geometry>
        <mesh filename="package://full_vehicle_description/meshes/six_force_sensor_link.STL"/>
      </geometry>
      <material name="">
        <color rgba="1 1 1 1"/>
      </material>
    </visual>
    <collision>
      <origin rpy="0 0 0" xyz="0 0 0"/>
      <geometry>
        <!-- <mesh
          filename="package://full_vehicle_description/meshes/six_force_sensor_link.STL" /> -->
        <cylinder length="0.03" radius="0.034"/>
      </geometry>
    </collision>
  </link>
  <joint name="robot1_six_force_sensor_2_base_joint" type="fixed">
    <origin rpy="0 0 0" xyz="-0.2065 0 -0.54995"/>
    <parent link="robot1_six_force_sensor_link"/>
    <child link="robot1_base_link"/>
    <axis xyz="0 0 0"/>
  </joint>
  <link name="robot1_zhou_cheng_link">
    <inertial>
      <mass value="10"/>
      <inertia ixx="0.0036400000000000004" ixy="0" ixz="0" iyy="0.0036400000000000004" iyz="0" izz="0.00578"/>
    </inertial>
    <visual>
      <origin rpy="0 0 0" xyz="0 0 0"/>
      <geometry>
        <mesh filename="package://full_vehicle_description/meshes/zhou_cheng_link.STL"/>
      </geometry>
      <material name="">
        <color rgba="0.792156862745098 0.819607843137255 0.933333333333333 1"/>
      </material>
    </visual>
    <collision>
      <origin rpy="0 0 0" xyz="0 0 0"/>
      <geometry>
        <!-- <mesh
          filename="package://full_vehicle_description/meshes/zhou_cheng_link.STL" /> -->
        <cylinder length="0.03" radius="0.034"/>
      </geometry>
    </collision>
  </link>
  <joint name="robot1_zhou_cheng_2_six_force_sensor_joint" type="fixed">
    <origin rpy="0 0 0" xyz="0 0 -0.0350000000000001"/>
    <parent link="robot1_zhou_cheng_link"/>
    <child link="robot1_six_force_sensor_link"/>
    <axis xyz="0 0 0"/>
  </joint>
  <link name="robot1_hua_tai_link">
    <inertial>
      <mass value="10"/>
      <inertia ixx="0.03585416666666667" ixy="0" ixz="0" iyy="0.03466666666666667" iyz="0" izz="0.0038541666666666668"/>
    </inertial>
    <visual>
      <origin rpy="0 0 0" xyz="0 0 0"/>
      <geometry>
        <mesh filename="package://full_vehicle_description/meshes/hua_tai_link.STL"/>
      </geometry>
      <material name="">
        <color rgba="0.792156862745098 0.819607843137255 0.933333333333333 1"/>
      </material>
    </visual>
    <collision>
      <origin rpy="0 0 0" xyz="0 0 0"/>
      <geometry>
        <!-- <mesh
          filename="package://full_vehicle_description/meshes/hua_tai_link.STL" /> -->
        <box size="0.2 0.04 0.055"/>
      </geometry>
    </collision>
  </link>
  <joint name="robot1_hua_tai_2_zhou_cheng_joint" type="continuous">
    <dynamics friction="0.01"/>
    <origin rpy="0 0 0" xyz="0 0 -0.05005"/>
    <parent link="robot1_hua_tai_link"/>
    <child link="robot1_zhou_cheng_link"/>
    <axis xyz="0 0 -1"/>
  </joint>
  <joint name="robot1_fixed_hua_kuai_2_hua_tai_joint" type="prismatic">
    <dynamics friction="0.01"/>
    <origin rpy="0 0 0" xyz="0.007354 5E-05 -0.0355"/>
    <parent link="robot1_fixed_hua_kuai_link"/>
    <child link="robot1_hua_tai_link"/>
    <axis xyz="1 0 0"/>
    <limit effort="50" lower="-0.05" upper="0.05" velocity="1"/>
  </joint>
  <link name="robot1_fixed_hua_kuai_link">
    <inertial>
      <mass value="10"/>
      <inertia ixx="0.005666666666666667" ixy="0" ixz="0" iyy="0.006666666666666667" iyz="0" izz="0.0016666666666666668"/>
    </inertial>
    <visual>
      <origin rpy="0 0 0" xyz="0 0 0"/>
      <geometry>
        <mesh filename="package://full_vehicle_description/meshes/fixed_hua_kuai_link.STL"/>
      </geometry>
      <material name="">
        <color rgba="1 1 1 1"/>
      </material>
    </visual>
    <collision>
      <origin rpy="0 0 0" xyz="0 0 0"/>
      <geometry>
        <box size="0.08 0.04 0.02"/>
      </geometry>
    </collision>
  </link>
    <gazebo>
  <plugin name="robot1_ft_sensor" filename="libgazebo_ros_ft_sensor.so">
        <update_rate>30</update_rate>
        <topicName>/robot1_ft_sensor</topicName>
        <jointName>robot1_hua_tai_2_zhou_cheng_joint</jointName>
  </plugin>
  </gazebo>
</robot>